Workbook

Sheet BERÇÁRIO 1
A1: Avaliação Nutricional 2025/1 Berçário 1
B3: Data de Nasc. | C3: Data pesagem | D3: Idade | E3: Peso (kg) | F3: Estatura (m) | G3: IMC (kg/m²) | H3: IMC/I | I3: P/I | J3: E/I | K3: DIAGNÓSTICO NUTRICIONAL | N3: Menina | O3: Menino
A4: Ana Tanahashi F. Pereira | B4: 45601 | C4: 45748 | D4: 4 m | E4: 9.6 | F4: 0.73 | G4: =E4/F4/F4 -> 18.014637 | H4: 75-85 | I4: > 99 | J4: > 99 | K4: ADEQUADO | M4: Baixo peso
A5: Eduardo Luiz D. P. Filho | B5: 45365 | G5: =E5/(F5*F5) -> #DIV/0! | M5: Adequado | N5: 3 | O5: 1
A6: Enrico Oyama Buccini | B6: 45487 | C6: 45748 | D6: 8 m | E6: 8.5 | F6: 0.72 | G6: =E6/(F6*F6) -> 16.396605 | H6: 25-50 | I6: 25-50 | J6: 50-75 | K6: EUTROFIA | M6: Sobrepeso | N6: 1 | O6: 1
A7: Giulia Giuntoli Sinigaglia | B7: 45328 | C7: 45748 | D7: 1a 1m | E7: 10.7 | F7: 0.79 | G7: =E7/(F7*F7) -> 17.144688 | H7: 50-75 | I7: 85-95 | J7: 85-95 | K7: ADEQUADO | M7: Obesidade | N7: 1
A8: Heloísa Yukie Tina Herrera | B8: 45411 | C8: 45748 | D8: 11 m | E8: 7.7 | F8: 0.69 | G8: =E8/(F8*F8) -> 16.173073 | H8: 25-50 | I8: 15 | J8: 5-15. | K8: ADEQUADO | M8: Total / gênero | N8: =SUM(N5:N7) -> 5 | O8: =SUM(O5:O7) -> 2
A9: Julia Coda Amieiro | B9: 45394 | C9: 45748 | D9: 11 m | E9: 8.7 | F9: 0.69 | G9: =E9/(F9*F9) -> 18.273472 | H9: 85-95 | I9: 50 | J9: 5-15. | K9: SOBREPESO | M9: Total | O9: =SUM(N8:O8) -> 7
A10: Louise Oliveira Starke | B10: 45520 | C10: 45748 | D10: 7 m | E10: 9.8 | F10: 0.68 | G10: =E10/(F10*F10) -> 21.193772 | H10: > 99 | I10: 75-85 | J10: 50-75 | K10: OBESIDADE
A11: Matteo Manzi Trindade | B11: 45373 | C11: 45748 | D11: 1a | E11: 10 | F11: 0.74 | G11: =E11/(F11*F11) -> 18.261505 | H11: 85 | I11: 50-75 | J11: 15-25 | K11: SOBREPESO

Sheet Av. Individual B1
A1: Nome | B1: ='BERÇÁRIO 1'!$A$4 -> Ana Tanahashi F. Pereira | E1: DN | F1: ='BERÇÁRIO 1'!$B$4 -> 45601 | H1: Nome | I1: =#REF! -> #REF! | L1: DN | M1: =#REF! -> #REF!
A2: Nutricionista: Carina C. R. Xavier - CRN-3: 20.044 | H2: Nutricionista: Carina C. R. Xavier - CRN-3: 20.044
A3: Data | B3: ='BERÇÁRIO 1'!C4 -> 45748 | C3: Percentil | D3: Idade (anos) | F3: ='BERÇÁRIO 1'!D4 -> 4 m | H3: Data | I3: =#REF! -> #REF! | J3: Percentil | K3: Idade (anos) | M3: =#REF! -> #REF!
A4: Peso (kg) | B4: ='BERÇÁRIO 1'!$E$4 -> 9.6 | C4: ='BERÇÁRIO 1'!$I$4 -> > 99 | H4: Peso (kg) | I4: ='BERÇÁRIO 1'!$E$4 -> 9.6 | J4: =#REF! -> #REF!
A5: Estatura (m) | B5: ='BERÇÁRIO 1'!$F$4 -> 0.73 | C5: ='BERÇÁRIO 1'!$J$4 -> > 99 | H5: Estatura (m) | I5: ='BERÇÁRIO 1'!$F$4 -> 0.73 | J5: =#REF! -> #REF!
A6: IMC (kg/m²) | B6: ='BERÇÁRIO 1'!$G$4 -> 18.014637 | C6: ='BERÇÁRIO 1'!$H$4 -> 75-85 | H6: IMC (kg/m²) | I6: ='BERÇÁRIO 1'!$G$4 -> 18.014637 | J6: =#REF! -> #REF!
A7: Diagnóstico nutricional | B7: ='BERÇÁRIO 1'!K4 -> ADEQUADO | H7: Diagnóstico nutricional | I7: =#REF! -> #REF!
A9: Nome | B9: ='BERÇÁRIO 1'!A5 -> Eduardo Luiz D. P. Filho | E9: DN | F9: ='BERÇÁRIO 1'!B5 -> 45365 | H9: Nome | I9: =#REF! -> #REF! | L9: DN | M9: =#REF! -> #REF!
A10: Nutricionista: Carina C. R. Xavier - CRN-3: 20.044 | H10: Nutricionista: Carina C. R. Xavier - CRN-3: 20.044
A11: Data | B11: ='BERÇÁRIO 1'!C5 -> 0 | C11: Percentil | D11: Idade (anos) | F11: ='BERÇÁRIO 1'!D5 -> 0 | H11: Data | I11: =#REF! -> #REF! | J11: Percentil | K11: Idade (anos) | M11: =#REF! -> #REF!
A12: Peso (kg) | B12: ='BERÇÁRIO 1'!E5 -> 0 | C12: ='BERÇÁRIO 1'!I5 -> 0 | H12: Peso (kg) | I12: =#REF! -> #REF! | J12: =#REF! -> #REF!
A13: Estatura (m) | B13: ='BERÇÁRIO 1'!F5 -> 0 | C13: ='BERÇÁRIO 1'!J5 -> 0 | H13: Estatura (m) | I13: =#REF! -> #REF! | J13: =#REF! -> #REF!
A14: IMC (kg/m²) | B14: ='BERÇÁRIO 1'!G5 -> #DIV/0! | C14: ='BERÇÁRIO 1'!H5 -> 0 | H14: IMC (kg/m²) | I14: =#REF! -> #REF! | J14: =#REF! -> #REF!
A15: Diagnóstico nutricional | B15: ='BERÇÁRIO 1'!K5 -> 0 | H15: Diagnóstico nutricional | I15: =#REF! -> #REF!
A17: Nome | B17: ='BERÇÁRIO 1'!A9 -> Julia Coda Amieiro | E17: DN | F17: ='BERÇÁRIO 1'!B9 -> 45394 | H17: Nome | I17: ='BERÇÁRIO 1'!#REF! -> #REF! | L17: DN | M17: ='BERÇÁRIO 1'!#REF! -> #REF!
A18: Nutricionista: Carina C. R. Xavier - CRN-3: 20.044 | H18: Nutricionista: Carina C. R. Xavier - CRN-3: 20.044
A19: Data | B19: ='BERÇÁRIO 1'!C9 -> 45748 | C19: Percentil | D19: Idade | F19: ='BERÇÁRIO 1'!D9 -> 11 m | H19: Data | I19: =#REF! -> #REF! | J19: Percentil | K19: Idade (anos) | M19: ='BERÇÁRIO 1'!#REF! -> #REF!
A20: Peso (kg) | B20: ='BERÇÁRIO 1'!E9 -> 8.7 | C20: ='BERÇÁRIO 1'!I9 -> 50 | H20: Peso (kg) | I20: ='BERÇÁRIO 1'!#REF! -> #REF! | J20: ='BERÇÁRIO 1'!#REF! -> #REF!
A21: Estatura (m) | B21: ='BERÇÁRIO 1'!F9 -> 0.69 | C21: ='BERÇÁRIO 1'!J9 -> 5-15. | H21: Estatura (m) | I21: ='BERÇÁRIO 1'!#REF! -> #REF! | J21: ='BERÇÁRIO 1'!#REF! -> #REF!
A22: IMC (kg/m²) | B22: ='BERÇÁRIO 1'!G9 -> 18.273472 | C22: ='BERÇÁRIO 1'!H9 -> 85-95 | H22: IMC (kg/m²) | I22: ='BERÇÁRIO 1'!#REF! -> #REF! | J22: ='BERÇÁRIO 1'!#REF! -> #REF!
A23: Diagnóstico nutricional | B23: ='BERÇÁRIO 1'!K9 -> SOBREPESO | H23: Diagnóstico nutricional | I23: ='BERÇÁRIO 1'!#REF! -> #REF!
A25: Nome | B25: ='BERÇÁRIO 1'!A10 -> Louise Oliveira Starke | E25: DN | F25: ='BERÇÁRIO 1'!B10 -> 45520 | H25: Nome | I25: ='BERÇÁRIO 1'!#REF! -> #REF! | L25: DN | M25: ='BERÇÁRIO 1'!#REF! -> #REF!
A26: Nutricionista: Carina C. R. Xavier - CRN-3: 20.044 | H26: Nutricionista: Carina C. R. Xavier - CRN-3: 20.044
A27: Data | B27: ='BERÇÁRIO 1'!C12 -> 0 | C27: Percentil | D27: Idade (anos) | F27: ='BERÇÁRIO 1'!D10 -> 7 m | H27: Data | I27: ='BERÇÁRIO 1'!#REF! -> #REF! | J27: Percentil | K27: Idade (anos) | M27: ='BERÇÁRIO 1'!#REF! -> #REF!
A28: Peso (kg) | B28: ='BERÇÁRIO 1'!E10 -> 9.8 | C28: ='BERÇÁRIO 1'!I10 -> 75-85 | H28: Peso (kg) | I28: ='BERÇÁRIO 1'!#REF! -> #REF! | J28: ='BERÇÁRIO 1'!#REF! -> #REF!
A29: Estatura (m) | B29: ='BERÇÁRIO 1'!F10 -> 0.68 | C29: ='BERÇÁRIO 1'!J10 -> 50-75 | H29: Estatura (m) | I29: ='BERÇÁRIO 1'!#REF! -> #REF! | J29: ='BERÇÁRIO 1'!#REF! -> #REF!
A30: IMC (kg/m²) | B30: ='BERÇÁRIO 1'!G10 -> 21.193772 | C30: ='BERÇÁRIO 1'!H10 -> > 99 | H30: IMC (kg/m²) | I30: ='BERÇÁRIO 1'!#REF! -> #REF! | J30: ='BERÇÁRIO 1'!#REF! -> #REF!
A31: Diagnóstico nutricional | B31: ='BERÇÁRIO 1'!K10 -> OBESIDADE | H31: Diagnóstico nutricional | I31: ='BERÇÁRIO 1'!#REF! -> #REF!
A33: Nome | B33: ='BERÇÁRIO 1'!A12 -> 0 | E33: DN | F33: ='BERÇÁRIO 1'!B12 -> 0 | H33: Nome | I33: ='BERÇÁRIO 1'!#REF! -> #REF! | L33: DN | M33: ='BERÇÁRIO 1'!#REF! -> #REF!
A34: Nutricionista: Carina C. R. Xavier - CRN-3: 20.044 | H34: Nutricionista: Carina C. R. Xavier - CRN-3: 20.044
A35: Data | B35: ='BERÇÁRIO 1'!C12 -> 0 | C35: Percentil | D35: Idade (anos) | F35: ='BERÇÁRIO 1'!D12 -> 0 | H35: Data | I35: ='BERÇÁRIO 1'!#REF! -> #REF! | J35: Percentil | K35: Idade (anos) | M35: ='BERÇÁRIO 1'!#REF! -> #REF!
A36: Peso (kg) | B36: ='BERÇÁRIO 1'!E12 -> 0 | C36: ='BERÇÁRIO 1'!I12 -> 0 | H36: Peso (kg) | I36: ='BERÇÁRIO 1'!#REF! -> #REF! | J36: ='BERÇÁRIO 1'!#REF! -> #REF!
A37: Estatura (m) | B37: ='BERÇÁRIO 1'!F12 -> 0 | C37: ='BERÇÁRIO 1'!J12 -> 0 | H37: Estatura (m) | I37: ='BERÇÁRIO 1'!#REF! -> #REF! | J37: ='BERÇÁRIO 1'!#REF! -> #REF!
A38: IMC (kg/m²) | B38: ='BERÇÁRIO 1'!G12 -> 0 | C38: ='BERÇÁRIO 1'!H12 -> 0 | H38: IMC (kg/m²) | I38: ='BERÇÁRIO 1'!#REF! -> #REF! | J38: ='BERÇÁRIO 1'!#REF! -> #REF!
A39: Diagnóstico nutricional | B39: ='BERÇÁRIO 1'!K12 -> 0 | H39: Diagnóstico nutricional | I39: ='BERÇÁRIO 1'!#REF! -> #REF!

Sheet BERÇÁRIO 2
A1: Avaliação Nutricional 2025/1 - Berçário 2
B3: Data de Nasc. | C3: Data pesagem | D3: Idade | E3: Peso (kg) | F3: Estatura (m) | G3: IMC (kg/m²) | H3: IMC/I | I3: P/I | J3: E/I | K3: DIAGNÓSTICO NUTRICIONAL | N3: Menina | O3: Menino
A4: Bernardo Enju Orbite | B4: 45199 | G4: =E4/(F4*F4) -> #DIV/0! | M4: Baixo peso
A5: Bianca Simioni Cavalieri | B5: 45204 | C5: 45729 | D5: 1a 5m | E5: 10.1 | F5: 0.79 | G5: =E5/(F5*F5) -> 16.183304 | H5: 50-75 | I5: 50-75 | J5: 25-50 | K5: ADEQUADO | M5: Adequado | N5: 2
A6: Clara Mayumi H. Barbosa | B6: 45167 | C6: 45729 | D6: 1a 6m | E6: 10.7 | F6: 0.79 | G6: =E6/(F6*F6) -> 17.144688 | H6: 75-85 | I6: 50-75 | J6: 25-50 | K6: ADEQUADO | M6: Sobrepeso | O6: 2
A7: Gael Bello Bittencourt | B7: 45183 | C7: 45729 | D7: 1a 6m | E7: 13.8 | F7: 0.85 | G7: =E7/(F7*F7) -> 19.100346 | H7: 97-99 | I7: 97-99 | J7: 75-85 | K7: OBESIDADE | M7: Obesidade | O7: 1
A8: Guilherme Olhê P. Augusto | B8: 45155 | C8: 45729 | D8: 1a 6m | E8: 10.7 | F8: 0.78 | G8: =E8/(F8*F8) -> 17.587114 | H8: 85-95 | I8: 25-50 | J8: 5-15. | K8: SOBREPESO | M8: Total / gênero | N8: =SUM(N5:N7) -> 2 | O8: =SUM(O6:O7) -> 3
A9: Lucas Vieira Cutovoi | B9: 45209 | C9: 45729 | D9: 1a 5m | E9: 11.1 | F9: 0.79 | G9: =E9/(F9*F9) -> 17.785611 | H9: 85-95 | I9: 50-75 | J9: 15-25 | K9: SOBREPESO | M9: Total | O9: =SUM(N8:O8) -> 5

Sheet Av. Individual B2
A1: Nome | B1: ='BERÇÁRIO 2'!A4 -> Bernardo Enju Orbite | E1: DN | F1: ='BERÇÁRIO 2'!B4 -> 45199 | H1: Nome | I1: ='BERÇÁRIO 2'!A12 -> 0 | L1: DN | M1: ='BERÇÁRIO 2'!B12 -> 0
A2: Nutricionista: Carina C. R. Xavier - CRN-3: 20.044 | H2: Nutricionista: Carina C. R. Xavier - CRN-3: 20.044
A3: Data | B3: ='BERÇÁRIO 2'!C4 -> 0 | C3: Percentil | D3: Idade (anos) | F3: ='BERÇÁRIO 2'!D4 -> 0 | H3: Data | I3: ='BERÇÁRIO 2'!C12 -> 0 | J3: Percentil | K3: Idade (anos) | M3: ='BERÇÁRIO 2'!D12 -> 0
A4: Peso (kg) | B4: ='BERÇÁRIO 2'!E4 -> 0 | C4: ='BERÇÁRIO 2'!$I$4 -> 0 | H4: Peso (kg) | I4: ='BERÇÁRIO 2'!E12 -> 0 | J4: ='BERÇÁRIO 2'!I12 -> 0
A5: Estatura (m) | B5: ='BERÇÁRIO 2'!F4 -> 0 | C5: ='BERÇÁRIO 2'!$J$4 -> 0 | H5: Estatura (m) | I5: ='BERÇÁRIO 2'!F12 -> 0 | J5: ='BERÇÁRIO 2'!J12 -> 0
A6: IMC (kg/m²) | B6: ='BERÇÁRIO 2'!G4 -> #DIV/0! | C6: ='BERÇÁRIO 2'!$H$4 -> 0 | H6: IMC (kg/m²) | I6: ='BERÇÁRIO 2'!G12 -> 0 | J6: ='BERÇÁRIO 2'!H12 -> 0
A7: Diagnóstico nutricional | B7: ='BERÇÁRIO 2'!K4 -> 0 | H7: Diagnóstico nutricional | I7: ='BERÇÁRIO 2'!K12 -> 0
A9: Nome | B9: ='BERÇÁRIO 2'!A5 -> Bianca Simioni Cavalieri | E9: DN | F9: ='BERÇÁRIO 2'!B5 -> 45204 | H9: Nome | I9: ='BERÇÁRIO 2'!A13 -> 0 | L9: DN | M9: ='BERÇÁRIO 2'!B13 -> 0
A10: Nutricionista: Carina C. R. Xavier - CRN-3: 20.044 | H10: Nutricionista: Carina C. R. Xavier - CRN-3: 20.044
A11: Data | B11: ='BERÇÁRIO 2'!C5 -> 45729 | C11: Percentil | D11: Idade (anos) | F11: ='BERÇÁRIO 2'!D5 -> 1a 5m | H11: Data | I11: ='BERÇÁRIO 2'!C13 -> 0 | J11: Percentil | K11: Idade (anos) | M11: ='BERÇÁRIO 2'!D13 -> 0
A12: Peso (kg) | B12: ='BERÇÁRIO 2'!E5 -> 10.1 | C12: ='BERÇÁRIO 2'!I5 -> 50-75 | H12: Peso (kg) | I12: ='BERÇÁRIO 2'!E13 -> 0 | J12: ='BERÇÁRIO 2'!I13 -> 0
A13: Estatura (m) | B13: ='BERÇÁRIO 2'!F5 -> 0.79 | C13: ='BERÇÁRIO 2'!J5 -> 25-50 | H13: Estatura (m) | I13: ='BERÇÁRIO 2'!F13 -> 0 | J13: ='BERÇÁRIO 2'!J13 -> 0
A14: IMC (kg/m²) | B14: ='BERÇÁRIO 2'!G5 -> 16.183304 | C14: ='BERÇÁRIO 2'!H5 -> 50-75 | H14: IMC (kg/m²) | I14: ='BERÇÁRIO 2'!G13 -> 0 | J14: ='BERÇÁRIO 2'!H13 -> 0
A15: Diagnóstico nutricional | B15: ='BERÇÁRIO 2'!K5 -> ADEQUADO | H15: Diagnóstico nutricional | I15: ='BERÇÁRIO 2'!K13 -> 0
A17: Nome | B17: ='BERÇÁRIO 2'!A6 -> Clara Mayumi H. Barbosa | E17: DN | F17: ='BERÇÁRIO 2'!B6 -> 45167 | H17: Nome | I17: =#REF! -> #REF! | L17: DN | M17: =#REF! -> #REF!
A18: Nutricionista: Carina C. R. Xavier - CRN-3: 20.044 | H18: Nutricionista: Carina C. R. Xavier - CRN-3: 20.044
A19: Data | B19: ='BERÇÁRIO 2'!C6 -> 45729 | C19: Percentil | D19: Idade | F19: ='BERÇÁRIO 2'!D6 -> 1a 6m | H19: Data | I19: =#REF! -> #REF! | J19: Percentil | K19: Idade (anos) | M19: =#REF! -> #REF!
A20: Peso (kg) | B20: ='BERÇÁRIO 2'!E6 -> 10.7 | C20: ='BERÇÁRIO 2'!I6 -> 50-75 | H20: Peso (kg) | I20: =#REF! -> #REF! | J20: =#REF! -> #REF!
A21: Estatura (m) | B21: ='BERÇÁRIO 2'!F6 -> 0.79 | C21: ='BERÇÁRIO 2'!J6 -> 25-50 | H21: Estatura (m) | I21: =#REF! -> #REF! | J21: =#REF! -> #REF!
A22: IMC (kg/m²) | B22: ='BERÇÁRIO 2'!G6 -> 17.144688 | C22: ='BERÇÁRIO 2'!H6 -> 75-85 | H22: IMC (kg/m²) | I22: =#REF! -> #REF! | J22: =#REF! -> #REF!
A23: Diagnóstico nutricional | B23: ='BERÇÁRIO 2'!K6 -> ADEQUADO | H23: Diagnóstico nutricional | I23: =#REF! -> #REF!
A25: Nome | B25: ='BERÇÁRIO 2'!A7 -> Gael Bello Bittencourt | E25: DN | F25: ='BERÇÁRIO 2'!B9 -> 45209 | H25: Nome | I25: =#REF! -> #REF! | L25: DN | M25: =#REF! -> #REF!
A26: Nutricionista: Carina C. R. Xavier - CRN-3: 20.044 | H26: Nutricionista: Carina C. R. Xavier - CRN-3: 20.044
A27: Data | B27: ='BERÇÁRIO 2'!C7 -> 45729 | C27: Percentil | D27: Idade | F27: ='BERÇÁRIO 2'!D9 -> 1a 5m | H27: Data | I27: =#REF! -> #REF! | J27: Percentil | K27: Idade (anos) | M27: =#REF! -> #REF!
A28: Peso (kg) | B28: ='BERÇÁRIO 2'!E7 -> 13.8 | C28: ='BERÇÁRIO 2'!I9 -> 50-75 | H28: Peso (kg) | I28: =#REF! -> #REF! | J28: =#REF! -> #REF!
A29: Estatura (m) | B29: ='BERÇÁRIO 2'!F7 -> 0.85 | C29: ='BERÇÁRIO 2'!J9 -> 15-25 | H29: Estatura (m) | I29: =#REF! -> #REF! | J29: =#REF! -> #REF!
A30: IMC (kg/m²) | B30: ='BERÇÁRIO 2'!G7 -> 19.100346 | C30: ='BERÇÁRIO 2'!H9 -> 85-95 | H30: IMC (kg/m²) | I30: =#REF! -> #REF! | J30: =#REF! -> #REF!
A31: Diagnóstico nutricional | B31: ='BERÇÁRIO 2'!K7 -> OBESIDADE | H31: Diagnóstico nutricional | I31: =#REF! -> #REF!
A33: Nome | B33: ='BERÇÁRIO 2'!A8 -> Guilherme Olhê P. Augusto | E33: DN | F33: ='BERÇÁRIO 2'!B8 -> 45155 | H33: Nome | I33: =#REF! -> #REF! | L33: DN | M33: =#REF! -> #REF!
A34: Nutricionista: Carina C. R. Xavier - CRN-3: 20.044 | H34: Nutricionista: Carina C. R. Xavier - CRN-3: 20.044
A35: Data | B35: ='BERÇÁRIO 2'!C8 -> 45729 | C35: Percentil | D35: Idade | F35: ='BERÇÁRIO 2'!D8 -> 1a 6m | H35: Data | I35: =#REF! -> #REF! | J35: Percentil | K35: Idade (anos) | M35: =#REF! -> #REF!
A36: Peso (kg) | B36: ='BERÇÁRIO 2'!E8 -> 10.7 | C36: ='BERÇÁRIO 2'!I10 -> 0 | H36: Peso (kg) | I36: =#REF! -> #REF! | J36: =#REF! -> #REF!
A37: Estatura (m) | B37: ='BERÇÁRIO 2'!F8 -> 0.78 | C37: ='BERÇÁRIO 2'!J10 -> 0 | H37: Estatura (m) | I37: =#REF! -> #REF! | J37: =#REF! -> #REF!
A38: IMC (kg/m²) | B38: ='BERÇÁRIO 2'!G8 -> 17.587114 | C38: ='BERÇÁRIO 2'!H10 -> 0 | H38: IMC (kg/m²) | I38: =#REF! -> #REF! | J38: =#REF! -> #REF!
A39: Diagnóstico nutricional | B39: ='BERÇÁRIO 2'!K8 -> SOBREPESO | H39: Diagnóstico nutricional | I39: =#REF! -> #REF!
A41: Nome | B41: ='BERÇÁRIO 2'!A9 -> Lucas Vieira Cutovoi | E41: DN | F41: ='BERÇÁRIO 2'!B9 -> 45209 | H41: Nome | I41: =#REF! -> #REF! | L41: DN | M41: =#REF! -> #REF!
A42: Nutricionista: Carina C. R. Xavier - CRN-3: 20.044 | H42: Nutricionista: Carina C. R. Xavier - CRN-3: 20.044
A43: Data | B43: ='BERÇÁRIO 2'!C9 -> 45729 | C43: Percentil | D43: Idade | F43: ='BERÇÁRIO 2'!D9 -> 1a 5m | H43: Data | I43: =#REF! -> #REF! | J43: Percentil | K43: Idade (anos) | M43: =#REF! -> #REF!
A44: Peso (kg) | B44: ='BERÇÁRIO 2'!E9 -> 11.1 | C44: ='BERÇÁRIO 2'!I9 -> 50-75 | H44: Peso (kg) | I44: =#REF! -> #REF! | J44: =#REF! -> #REF!
A45: Estatura (m) | B45: ='BERÇÁRIO 2'!F9 -> 0.79 | C45: ='BERÇÁRIO 2'!J9 -> 15-25 | H45: Estatura (m) | I45: =#REF! -> #REF! | J45: =#REF! -> #REF!
...

Sheet Mini Baby
A1: Avaliação Nutricional 2025/1 - Mini baby
B3: Data de Nasc. | C3: Data pesagem | D3: Idade | E3: Peso (kg) | F3: Estatura (m) | G3: IMC (kg/m²) | H3: IMC/I | I3: P/I | J3: E/I | K3: DIAGNÓSTICO NUTRICIONAL | N3: Menina | O3: Menino
A4: Átila Topic | B4: 45101 | C4: 45729 | D4: 1a 8m | E4: 14.2 | F4: 0.87 | G4: =E4/(F4*F4) -> 18.760735 | H4: 97-99 | I4: 97-99 | J4: 85-95 | K4: OBESIDADE | M4: Baixo peso
A5: Bernardo C. Melhado | B5: 45118 | C5: 45729 | D5: 1a 8m | E5: 11.8 | F5: 0.86 | G5: =E5/(F5*F5) -> 15.95457 | H5: 50 | I5: 50-75 | J5: 50-75 | K5: ADEQUADO | M5: Adequado | N5: 3 | O5: 2
A6: Camilo Bernardo Municelli | B6: 45068 | C6: 45729 | D6: 1a 9m | E6: 12.5 | F6: 0.86 | G6: =E6/(F6*F6) -> 16.901028 | H6: 75-85 | I6: 75 | J6: 50-75 | K6: ADEQUADO | M6: Sobrepeso | O6: 1
A7: Cecília P. Manfrín | B7: 45131 | C7: 45729 | D7: 1a 7m | E7: 11.8 | F7: 0.8 | G7: =E7/(F7*F7) -> 18.4375 | H7: 95-97 | I7: 75-85 | J7: 25-50 | K7: ADEQUADO | M7: Obesidade | N7: 1
A8: Helena dos Santos Pereira | B8: 45050 | C8: 45729 | D8: 1a 10m | E8: 10.4 | F8: 0.84 | G8: =E8/(F8*F8) -> 14.739229 | H8: 25-50 | I8: 25-50 | J8: 25-50 | K8: ADEQUADO | M8: Total / gênero | N8: =SUM(N7) -> 1 | O8: =SUM(O5:O7) -> 3
A9: Helena Torres Borini | B9: 45165 | C9: 45729 | D9: 1a 6m | E9: 11.4 | F9: 0.8 | G9: =E9/(F9*F9) -> 17.8125 | H9: 85-95 | I9: 75-85 | J9: 25-50 | K9: ADEQUADO | M9: Total | O9: =SUM(N8:O8) -> 4
A10: Luiggi Chiari Pieruzzi | B10: 45038 | C10: 45729 | D10: 1a 10m | E10: 13.9 | F10: 0.86 | G10: =E10/(F10*F10) -> 18.793943 | H10: 97-99 | I10: 95 | J10: 50 | K10: SOBREPESO
A11: Pérola de Lima B. Santos | B11: 45072 | G11: =E11/(F11*F11) -> #DIV/0!

Sheet Av. Individual MBaby
A1: Nome | B1: ='Mini Baby'!A4 -> Átila Topic | E1: DN | F1: ='Mini Baby'!B4 -> 45101 | H1: Nome | I1: ='Mini Baby'!A9 -> Helena Torres Borini | L1: DN | M1: ='Mini Baby'!B9 -> 45165
A2: Nutricionista: Carina C. R. Xavier - CRN-3: 20.044 | H2: Nutricionista: Carina C. R. Xavier - CRN-3: 20.044
A3: Data | B3: ='Mini Baby'!C4 -> 45729 | C3: Percentil | D3: Idade (anos) | F3: ='Mini Baby'!D4 -> 1a 8m | H3: Data | I3: ='Mini Baby'!C9 -> 45729 | J3: Percentil | K3: Idade (anos) | M3: ='Mini Baby'!D9 -> 1a 6m
A4: Peso (kg) | B4: ='Mini Baby'!E4 -> 14.2 | C4: ='Mini Baby'!I4 -> 97-99 | H4: Peso (kg) | I4: ='Mini Baby'!E9 -> 11.4 | J4: ='Mini Baby'!I9 -> 75-85
A5: Estatura (m) | B5: ='Mini Baby'!F4 -> 0.87 | C5: ='Mini Baby'!J4 -> 85-95 | H5: Estatura (m) | I5: ='Mini Baby'!F9 -> 0.8 | J5: ='Mini Baby'!J9 -> 25-50
A6: IMC (kg/m²) | B6: ='Mini Baby'!G4 -> 18.760735 | C6: ='Mini Baby'!H4 -> 97-99 | H6: IMC (kg/m²) | I6: ='Mini Baby'!G9 -> 17.8125 | J6: ='Mini Baby'!H9 -> 85-95
A7: Diagnóstico nutricional | B7: ='Mini Baby'!K4 -> OBESIDADE | H7: Diagnóstico nutricional | I7: ='Mini Baby'!K9 -> ADEQUADO
A9: Nome | B9: ='Mini Baby'!A5 -> Bernardo C. Melhado | E9: DN | F9: ='BERÇÁRIO 1'!$B$5 -> 45365 | H9: Nome | I9: ='Mini Baby'!A10 -> Luiggi Chiari Pieruzzi | L9: DN | M9: ='Mini Baby'!B10 -> 45038
A10: Nutricionista: Carina C. R. Xavier - CRN-3: 20.044 | H10: Nutricionista: Carina C. R. Xavier - CRN-3: 20.044
A11: Data | B11: ='Mini Baby'!C5 -> 45729 | C11: Percentil | D11: Idade (anos) | F11: ='Mini Baby'!D5 -> 1a 8m | H11: Data | I11: ='Mini Baby'!C10 -> 45729 | J11: Percentil | K11: Idade (anos) | M11: ='Mini Baby'!D10 -> 1a 10m
A12: Peso (kg) | B12: ='Mini Baby'!E5 -> 11.8 | C12: ='Mini Baby'!I5 -> 50-75 | H12: Peso (kg) | I12: ='Mini Baby'!E10 -> 13.9 | J12: ='Mini Baby'!I10 -> 95
A13: Estatura (m) | B13: ='Mini Baby'!F5 -> 0.86 | C13: ='Mini Baby'!J5 -> 50-75 | H13: Estatura (m) | I13: ='Mini Baby'!F10 -> 0.86 | J13: ='Mini Baby'!J10 -> 50
A14: IMC (kg/m²) | B14: ='Mini Baby'!G5 -> 15.95457 | C14: ='Mini Baby'!H5 -> 50 | H14: IMC (kg/m²) | I14: ='Mini Baby'!G10 -> 18.793943 | J14: ='Mini Baby'!H10 -> 97-99
A15: Diagnóstico nutricional | B15: ='Mini Baby'!K5 -> ADEQUADO | H15: Diagnóstico nutricional | I15: ='Mini Baby'!K10 -> SOBREPESO
A17: Nome | B17: ='Mini Baby'!A6 -> Camilo Bernardo Municelli | E17: DN | F17: ='BERÇÁRIO 1'!$B$9 -> 45394 | H17: Nome | I17: ='Mini Baby'!A11 -> Pérola de Lima B. Santos | L17: DN | M17: ='Mini Baby'!B11 -> 45072
A18: Nutricionista: Carina C. R. Xavier - CRN-3: 20.044 | H18: Nutricionista: Carina C. R. Xavier - CRN-3: 20.044
A19: Data | B19: ='Mini Baby'!C6 -> 45729 | C19: Percentil | D19: Idade (anos) | F19: ='Mini Baby'!D6 -> 1a 9m | H19: Data | I19: ='Mini Baby'!C11 -> 0 | J19: Percentil | K19: Idade (anos) | M19: ='Mini Baby'!D11 -> 0
A20: Peso (kg) | B20: ='Mini Baby'!E6 -> 12.5 | C20: ='Mini Baby'!I6 -> 75 | H20: Peso (kg) | I20: ='Mini Baby'!E11 -> 0 | J20: ='Mini Baby'!I11 -> 0
A21: Estatura (m) | B21: ='Mini Baby'!F6 -> 0.86 | C21: ='Mini Baby'!J6 -> 50-75 | H21: Estatura (m) | I21: ='Mini Baby'!F11 -> 0 | J21: ='Mini Baby'!J11 -> 0
A22: IMC (kg/m²) | B22: ='Mini Baby'!G6 -> 16.901028 | C22: ='Mini Baby'!H6 -> 75-85 | H22: IMC (kg/m²) | I22: ='Mini Baby'!G11 -> #DIV/0! | J22: ='Mini Baby'!H11 -> 0
A23: Diagnóstico nutricional | B23: ='Mini Baby'!K6 -> ADEQUADO | H23: Diagnóstico nutricional | I23: ='Mini Baby'!K11 -> 0
A25: Nome | B25: ='Mini Baby'!A7 -> Cecília P. Manfrín | E25: DN | F25: ='BERÇÁRIO 1'!$B$10 -> 45520 | H25: Nome | I25: ='Mini Baby'!A12 -> 0 | L25: DN | M25: ='Mini Baby'!B12 -> 0
A26: Nutricionista: Carina C. R. Xavier - CRN-3: 20.044 | H26: Nutricionista: Carina C. R. Xavier - CRN-3: 20.044
A27: Data | B27: ='Mini Baby'!C7 -> 45729 | C27: Percentil | D27: Idade (anos) | F27: ='Mini Baby'!D7 -> 1a 7m | H27: Data | I27: ='Mini Baby'!C12 -> 0 | J27: Percentil | K27: Idade (anos) | M27: ='Mini Baby'!D12 -> 0
A28: Peso (kg) | B28: ='Mini Baby'!E7 -> 11.8 | C28: ='Mini Baby'!I7 -> 75-85 | H28: Peso (kg) | I28: ='Mini Baby'!E12 -> 0 | J28: ='Mini Baby'!I12 -> 0
A29: Estatura (m) | B29: ='Mini Baby'!F7 -> 0.8 | C29: ='Mini Baby'!J7 -> 25-50 | H29: Estatura (m) | I29: ='Mini Baby'!F12 -> 0 | J29: ='Mini Baby'!J12 -> 0
A30: IMC (kg/m²) | B30: ='Mini Baby'!G7 -> 18.4375 | C30: ='Mini Baby'!H7 -> 95-97 | H30: IMC (kg/m²) | I30: ='Mini Baby'!G12 -> 0 | J30: ='Mini Baby'!H12 -> 0
A31: Diagnóstico nutricional | B31: ='Mini Baby'!K7 -> ADEQUADO | H31: Diagnóstico nutricional | I31: ='Mini Baby'!K12 -> 0
A33: Nome | B33: ='Mini Baby'!A8 -> Helena dos Santos Pereira | E33: DN | F33: ='BERÇÁRIO 1'!$B$12 -> 0 | H33: Nome | I33: ='Mini Baby'!A13 -> 0 | L33: DN | M33: ='Mini Baby'!B13 -> 0
A34: Nutricionista: Carina C. R. Xavier - CRN-3: 20.044 | H34: Nutricionista: Carina C. R. Xavier - CRN-3: 20.044
A35: Data | B35: ='Mini Baby'!C8 -> 45729 | C35: Percentil | D35: Idade (anos) | F35: ='Mini Baby'!D8 -> 1a 10m | H35: Data | I35: ='Mini Baby'!C13 -> 0 | J35: Percentil | K35: Idade (anos) | M35: ='Mini Baby'!D13 -> 0
A36: Peso (kg) | B36: ='Mini Baby'!E8 -> 10.4 | C36: ='Mini Baby'!I8 -> 25-50 | H36: Peso (kg) | I36: ='Mini Baby'!E13 -> 0 | J36: ='Mini Baby'!I13 -> 0
A37: Estatura (m) | B37: ='Mini Baby'!F8 -> 0.84 | C37: ='Mini Baby'!J8 -> 25-50 | H37: Estatura (m) | I37: ='Mini Baby'!F13 -> 0 | J37: ='Mini Baby'!J13 -> 0
A38: IMC (kg/m²) | B38: ='Mini Baby'!G8 -> 14.739229 | C38: ='Mini Baby'!H8 -> 25-50 | H38: IMC (kg/m²) | I38: ='Mini Baby'!G13 -> 0 | J38: ='Mini Baby'!H13 -> 0
A39: Diagnóstico nutricional | B39: ='Mini Baby'!K8 -> ADEQUADO | H39: Diagnóstico nutricional | I39: ='Mini Baby'!K13 -> 0
H41: Nome | I41: =#REF! -> #REF! | L41: DN | M41: =#REF! -> #REF!
H42: Nutricionista: Carina C. R. Xavier - CRN-3: 20.044
H43: Data | I43: =#REF! -> #REF! | J43: Percentil | K43: Idade (anos) | M43: =#REF! -> #REF!
H44: Peso (kg) | I44: =#REF! -> #REF! | J44: =#REF! -> #REF!
H45: Estatura (m) | I45: =#REF! -> #REF! | J45: =#REF! -> #REF!
...

Sheet Mini Maternal A
A1: Avaliação Nutricional 2025/1 - Mini Maternal A
B3: Data de Nasc. | C3: Data pesagem | D3: Idade | E3: Peso (kg) | F3: Estatura (m) | G3: IMC (kg/m²) | H3: IMC/I | I3: P/I | J3: E/I | K3: DIAGNÓSTICO NUTRICIONAL | N3: Menina | O3: Menino
A4: Alice Del Cistia Magalhães | B4: 44708 | C4: 45729 | D4: 2a 9m | E4: 12.2 | F4: 0.91 | G4: =E4/(F4*F4) -> 14.73252 | H4: 25-50 | I4: 25 | J4: 25-50 | K4: ADEQUADO | M4: Baixo peso
A5: Beatriz B. Foster de Oliveira | B5: 44716 | C5: 45729 | D5: 2a 9m | E5: 10.9 | F5: 0.86 | G5: =E5/(F5*F5) -> 14.737696 | H5: 25-50 | I5: 5-15. | J5: 3 | K5: ADEQUADO | M5: Adequado | N5: 4 | O5: 4
A6: Clara Arjonilla Porazenka | B6: 44744 | C6: 45729 | D6: 2a 8m | E6: 14.1 | F6: 0.91 | G6: =E6/(F6*F6) -> 17.026929 | H6: 85-95 | I6: 50-75 | J6: 25-50 | K6: SOBREPESO | M6: Sobrepeso | N6: 2
A7: Eli Zaroni Vieira | B7: 44817 | C7: 45729 | D7: 2a 6m | E7: 16.8 | F7: 0.94 | G7: =E7/(F7*F7) -> 19.013128 | H7: 97-99 | I7: 97-99 | J7: 50-75 | K7: OBESIDADE | M7: Obesidade | O7: 1
A8: Isabela Buzzini Casa Vechia | B8: 19/07/2022 | C8: 45729 | D8: 2a 7m | E8: 14.9 | F8: 0.92 | G8: =E8/(F8*F8) -> 17.60397 | H8: 85-95 | I8: 85-95 | J8: 50-75 | K8: SOBREPESO | M8: Total / gênero | N8: =SUM(N5:N7) -> 6 | O8: =SUM(O7) -> 1
A9: Lucas Barbosa Perez | B9: 44842 | C9: 45729 | D9: 2a 5m | E9: 12.1 | F9: 0.92 | G9: =E9/(F9*F9) -> 14.295841 | H9: 5-15. | I9: 25 | J9: 50-75 | K9: ADEQUADO | M9: Total | O9: =SUM(N8:O8) -> 7
A10: Manuela M. M. S. G. da Costa | B10: 44922 | C10: 45729 | D10: 2a 2m | E10: 12.2 | F10: 0.85 | G10: =E10/(F10*F10) -> 16.885813 | H10: 75-85 | I10: 50-75 | J10: 15-25 | K10: ADEQUADO
A11: Olívia Pereira Menezes | B11: 44989 | C11: 45729 | D11: 2a | E11: 10.4 | F11: 0.82 | G11: =E11/(F11*F11) -> 15.466984 | H11: 25-50 | I11: 15-25 | J11: 5-15. | K11: ADEQUADO
A12: Pedro Rodrigues Gomes | B12: 44748 | C12: 45729 | D12: 2a 8m | E12: 11.5 | F12: 0.86 | G12: =E12/(F12*F12) -> 15.548945 | H12: 25-50 | I12: 5-15. | J12: 1-3. | K12: ADEQUADO
A13: Téo Formaggio Pereira | B13: 44974 | C13: 45729 | D13: 2a | E13: 10.4 | F13: 0.84 | G13: =E13/(F13*F13) -> 14.739229 | H13: 5-15. | I13: 5-15. | J13: 15-25 | K13: ADEQUADO
A14: Théo Silva Oliveira | B14: 44803 | C14: 45729 | D14: 2a 6m | E14: 13.4 | F14: 0.91 | G14: =E14/(F14*F14) -> 16.181621 | H14: 50-75 | I14: 50-75 | J14: 25-50 | K14: ADEQUADO

Sheet Av. Individual MMA
A1: Nome | B1: ='Mini Maternal A'!A4 -> Alice Del Cistia Magalhães | E1: DN | F1: ='Mini Maternal A'!B4 -> 44708 | H1: Nome | I1: ='Mini Maternal A'!A9 -> Lucas Barbosa Perez | L1: DN | M1: ='Mini Maternal A'!B9 -> 44842
A2: Nutricionista: Carina C. R. Xavier - CRN-3: 20.044 | H2: Nutricionista: Carina C. R. Xavier - CRN-3: 20.044
A3: Data | B3: ='Mini Maternal A'!C4 -> 45729 | C3: Percentil | D3: Idade | F3: ='Mini Maternal A'!D4 -> 2a 9m | H3: Data | I3: ='Mini Maternal A'!C9 -> 45729 | J3: Percentil | K3: Idade (anos) | M3: ='Mini Maternal A'!D9 -> 2a 5m
A4: Peso (kg) | B4: ='Mini Maternal A'!E4 -> 12.2 | C4: ='Mini Maternal A'!I4 -> 25 | H4: Peso (kg) | I4: ='Mini Maternal A'!E9 -> 12.1 | J4: ='Mini Maternal A'!I9 -> 25
A5: Estatura (m) | B5: ='Mini Maternal A'!F4 -> 0.91 | C5: ='Mini Maternal A'!J4 -> 25-50 | H5: Estatura (m) | I5: ='Mini Maternal A'!F9 -> 0.92 | J5: ='Mini Maternal A'!J9 -> 50-75
A6: IMC (kg/m²) | B6: ='Mini Maternal A'!G4 -> 14.73252 | C6: ='Mini Maternal A'!H4 -> 25-50 | H6: IMC (kg/m²) | I6: ='Mini Maternal A'!G9 -> 14.295841 | J6: ='Mini Maternal A'!H9 -> 5-15.
A7: Diagnóstico nutricional | B7: ='Mini Maternal A'!K4 -> ADEQUADO | H7: Diagnóstico nutricional | I7: ='Mini Maternal A'!K9 -> ADEQUADO
A9: Nome | B9: ='Mini Maternal A'!A5 -> Beatriz B. Foster de Oliveira | E9: DN | F9: ='Mini Maternal A'!B5 -> 44716 | H9: Nome | I9: ='Mini Maternal A'!A10 -> Manuela M. M. S. G. da Costa | L9: DN | M9: ='Mini Maternal A'!B10 -> 44922
A10: Nutricionista: Carina C. R. Xavier - CRN-3: 20.044 | H10: Nutricionista: Carina C. R. Xavier - CRN-3: 20.044
A11: Data | B11: ='Mini Maternal A'!C5 -> 45729 | C11: Percentil | D11: Idade | F11: ='Mini Maternal A'!D5 -> 2a 9m | H11: Data | I11: ='Mini Maternal A'!C10 -> 45729 | J11: Percentil | K11: Idade (anos) | M11: ='Mini Maternal A'!D10 -> 2a 2m
A12: Peso (kg) | B12: ='Mini Maternal A'!E5 -> 10.9 | C12: ='Mini Maternal A'!I5 -> 5-15. | H12: Peso (kg) | I12: ='Mini Maternal A'!E10 -> 12.2 | J12: ='Mini Maternal A'!I10 -> 50-75
A13: Estatura (m) | B13: ='Mini Maternal A'!F5 -> 0.86 | C13: ='Mini Maternal A'!J5 -> 3 | H13: Estatura (m) | I13: ='Mini Maternal A'!F10 -> 0.85 | J13: ='Mini Maternal A'!J10 -> 15-25
A14: IMC (kg/m²) | B14: ='Mini Maternal A'!G5 -> 14.737696 | C14: ='Mini Maternal A'!H5 -> 25-50 | H14: IMC (kg/m²) | I14: ='Mini Maternal A'!G10 -> 16.885813 | J14: ='Mini Maternal A'!H10 -> 75-85
A15: Diagnóstico nutricional | B15: ='Mini Maternal A'!K5 -> ADEQUADO | H15: Diagnóstico nutricional | I15: ='Mini Maternal A'!K10 -> ADEQUADO
A17: Nome | B17: ='Mini Maternal A'!A6 -> Clara Arjonilla Porazenka | E17: DN | F17: ='Mini Maternal A'!B6 -> 44744 | H17: Nome | I17: ='Mini Maternal A'!A11 -> Olívia Pereira Menezes | L17: DN | M17: ='Mini Maternal A'!B11 -> 44989
A18: Nutricionista: Carina C. R. Xavier - CRN-3: 20.044 | H18: Nutricionista: Carina C. R. Xavier - CRN-3: 20.044
A19: Data | B19: ='Mini Maternal A'!C6 -> 45729 | C19: Percentil | D19: Idade | F19: ='Mini Maternal A'!D6 -> 2a 8m | H19: Data | I19: ='Mini Maternal A'!C11 -> 45729 | J19: Percentil | K19: Idade (anos) | M19: ='Mini Maternal A'!D11 -> 2a
A20: Peso (kg) | B20: ='Mini Maternal A'!E6 -> 14.1 | C20: ='Mini Maternal A'!I6 -> 50-75 | H20: Peso (kg) | I20: ='Mini Maternal A'!E11 -> 10.4 | J20: ='Mini Maternal A'!I11 -> 15-25
A21: Estatura (m) | B21: ='Mini Maternal A'!F6 -> 0.91 | C21: ='Mini Maternal A'!J6 -> 25-50 | H21: Estatura (m) | I21: ='Mini Maternal A'!F11 -> 0.82 | J21: ='Mini Maternal A'!J11 -> 5-15.
A22: IMC (kg/m²) | B22: ='Mini Maternal A'!G6 -> 17.026929 | C22: ='Mini Maternal A'!H6 -> 85-95 | H22: IMC (kg/m²) | I22: ='Mini Maternal A'!G11 -> 15.466984 | J22: ='Mini Maternal A'!H11 -> 25-50
A23: Diagnóstico nutricional | B23: ='Mini Maternal A'!K6 -> SOBREPESO | H23: Diagnóstico nutricional | I23: ='Mini Maternal A'!K11 -> ADEQUADO
A25: Nome | B25: ='Mini Maternal A'!A7 -> Eli Zaroni Vieira | E25: DN | F25: ='Mini Maternal A'!B7 -> 44817 | H25: Nome | I25: ='Mini Maternal A'!A12 -> Pedro Rodrigues Gomes | L25: DN | M25: ='Mini Maternal A'!B12 -> 44748
A26: Nutricionista: Carina C. R. Xavier - CRN-3: 20.044 | H26: Nutricionista: Carina C. R. Xavier - CRN-3: 20.044
A27: Data | B27: ='Mini Maternal A'!C7 -> 45729 | C27: Percentil | D27: Idade | F27: ='Mini Maternal A'!D7 -> 2a 6m | H27: Data | I27: ='Mini Maternal A'!C12 -> 45729 | J27: Percentil | K27: Idade (anos) | M27: ='Mini Maternal A'!D12 -> 2a 8m
A28: Peso (kg) | B28: ='Mini Maternal A'!E7 -> 16.8 | C28: ='Mini Maternal A'!I7 -> 97-99 | H28: Peso (kg) | I28: ='Mini Maternal A'!E12 -> 11.5 | J28: ='Mini Maternal A'!I12 -> 5-15.
A29: Estatura (m) | B29: ='Mini Maternal A'!F7 -> 0.94 | C29: ='Mini Maternal A'!J7 -> 50-75 | H29: Estatura (m) | I29: ='Mini Maternal A'!F12 -> 0.86 | J29: ='Mini Maternal A'!J12 -> 1-3.
A30: IMC (kg/m²) | B30: ='Mini Maternal A'!G7 -> 19.013128 | C30: ='Mini Maternal A'!H7 -> 97-99 | H30: IMC (kg/m²) | I30: ='Mini Maternal A'!G12 -> 15.548945 | J30: ='Mini Maternal A'!H12 -> 25-50
A31: Diagnóstico nutricional | B31: ='Mini Maternal A'!K7 -> OBESIDADE | H31: Diagnóstico nutricional | I31: ='Mini Maternal A'!K12 -> ADEQUADO
A33: Nome | B33: ='Mini Maternal A'!A8 -> Isabela Buzzini Casa Vechia | E33: DN | F33: ='Mini Maternal A'!B8 -> 19/07/2022 | H33: Nome | I33: ='Mini Maternal A'!A13 -> Téo Formaggio Pereira | L33: DN | M33: ='Mini Maternal A'!B13 -> 44974
A34: Nutricionista: Carina C. R. Xavier - CRN-3: 20.044 | H34: Nutricionista: Carina C. R. Xavier - CRN-3: 20.044
A35: Data | B35: ='Mini Maternal A'!C8 -> 45729 | C35: Percentil | D35: Idade | F35: ='Mini Maternal A'!D8 -> 2a 7m | H35: Data | I35: ='Mini Maternal A'!C13 -> 45729 | J35: Percentil | K35: Idade (anos) | M35: ='Mini Maternal A'!D13 -> 2a
A36: Peso (kg) | B36: ='Mini Maternal A'!E8 -> 14.9 | C36: ='Mini Maternal A'!I8 -> 85-95 | H36: Peso (kg) | I36: ='Mini Maternal A'!E13 -> 10.4 | J36: ='Mini Maternal A'!I13 -> 5-15.
A37: Estatura (m) | B37: ='Mini Maternal A'!F8 -> 0.92 | C37: ='Mini Maternal A'!J8 -> 50-75 | H37: Estatura (m) | I37: ='Mini Maternal A'!F13 -> 0.84 | J37: ='Mini Maternal A'!J13 -> 15-25
A38: IMC (kg/m²) | B38: ='Mini Maternal A'!G8 -> 17.60397 | C38: ='Mini Maternal A'!H8 -> 85-95 | H38: IMC (kg/m²) | I38: ='Mini Maternal A'!G13 -> 14.739229 | J38: ='Mini Maternal A'!H13 -> 5-15.
A39: Diagnóstico nutricional | B39: ='Mini Maternal A'!K8 -> SOBREPESO | H39: Diagnóstico nutricional | I39: ='Mini Maternal A'!K13 -> ADEQUADO

Sheet Mini Maternal B
A1: Avaliação Nutricional 2025/1 - Mini maternal B
B3: Data de Nasc. | C3: Data pesagem | D3: Idade | E3: Peso (kg) | F3: Estatura (m) | G3: IMC (kg/m²) | H3: IMC/I | I3: P/I | J3: E/I | K3: DIAGNÓSTICO NUTRICIONAL | N3: Menina | O3: Menino
A4: Bella P. D'Acunto T. Viera | B4: 44968 | C4: 45729 | D4: 2a 1m | E4: 11.3 | F4: 0.85 | G4: =E4/(F4*F4) -> 15.640138 | H4: 25-50 | I4: 25-50 | J4: 25-50 | K4: ADEQUADO | M4: Baixo peso
A5: Giovanna Gianini Freitas | B5: 44758 | C5: 45729 | D5: 2a 7m | E5: 14 | F5: 0.94 | G5: =E5/(F5*F5) -> 15.844273 | H5: 50-75 | I5: 50-75 | J5: 75-85 | K5: ADEQUADO | M5: Adequado | N5: 5 | O5: 4
A6: Heitor F. S. Lourenço | B6: 44845 | G6: =E6/(F6*F6) -> #DIV/0! | M6: Sobrepeso | O6: 1
A7: Henrique M. Gonçalves | B7: 44668 | C7: 45729 | D7: 2a 10m | E7: 14.4 | F7: 1 | G7: =E7/(F7*F7) -> 14.4 | H7: 15 | I7: 50-75 | J7: 85-95 | K7: ADEQUADO | M7: Obesidade
A8: Jorge Cavalheiro Mauá Diba | B8: 44743 | C8: 45729 | D8: 2a 8m | E8: 16 | F8: 0.95 | G8: =E8/(F8*F8) -> 17.728532 | H8: 85-95 | I8: 85-95 | J8: 50-75 | K8: SOBREPESO | M8: Total / gênero | N8: =SUM(N5:N7) -> 5 | O8: =SUM(O5:O7) -> 5
A9: Julia Gianini Freitas | B9: 44758 | C9: 45729 | D9: 2a 7m | E9: 14.8 | F9: 0.94 | G9: =E9/(F9*F9) -> 16.74966 | H9: 75-85 | I9: 85-95 | J9: 75-85 | K9: ADEQUADO | M9: Total | O9: =SUM(N8:O8) -> 10
A10: Malu Costa M. Pereira | B10: 44843 | C10: 45729 | D10: 2a 5m | E10: 11.6 | F10: 0.87 | G10: =E10/(F10*F10) -> 15.32567 | H10: 25-50 | I10: 25-50 | J10: 15-25 | K10: ADEQUADO
A11: Noah Lacativa Penna | B11: 44700 | C11: 45729 | D11: 2a 9m | E11: 15.1 | F11: 0.97 | G11: =E11/(F11*F11) -> 16.048464 | H11: 50-75 | I11: 75-85 | J11: 75-85 | K11: ADEQUADO
A12: Pedro M.Augusto de Souza | B12: 44718 | C12: 45729 | D12: 2a 9m | E12: 15.3 | F12: 0.98 | G12: =E12/(F12*F12) -> 15.930862 | H12: 50-75 | I12: 75-85 | J12: 85-95 | K12: ADEQUADO
A13: Rafaela Saori Teruya Lima | B13: 44994 | G13: =E13/(F13*F13) -> #DIV/0!
A14: Valentina Travagini Garcia | B14: 44813 | C14: 45729 | D14: 2a 6m | E14: 12.6 | F14: 0.89 | G14: =E14/(F14*F14) -> 15.907082 | H14: 50-75 | I14: 25-50 | J14: 25-50 | K14: ADEQUADO
A15: Vitor Lima Rodarte | B15: 09/12/2022 | C15: 45729 | D15: 2a 3m | E15: 12.8 | F15: 0.92 | G15: =E15/(F15*F15) -> 15.122873 | H15: 25 | I15: 50-75 | J15: 75-85 | K15: ADEQUADO

Sheet Av. Individual MMB
A1: Nome | B1: ='Mini Maternal B'!A4 -> Bella P. D'Acunto T. Viera | E1: DN | F1: ='Mini Maternal B'!B4 -> 44968 | H1: Nome | I1: ='Mini Maternal B'!A9 -> Julia Gianini Freitas | L1: DN | M1: ='Mini Maternal B'!B9 -> 44758
A2: Nutricionista: Carina C. R. Xavier - CRN-3: 20.044 | H2: Nutricionista: Carina C. R. Xavier - CRN-3: 20.044
A3: Data | B3: ='Mini Maternal B'!C4 -> 45729 | C3: Percentil | D3: Idade (anos) | F3: ='Mini Maternal B'!D4 -> 2a 1m | H3: Data | I3: ='Mini Maternal B'!C9 -> 45729 | J3: Percentil | K3: Idade (anos) | M3: ='Mini Maternal B'!D9 -> 2a 7m
A4: Peso (kg) | B4: ='Mini Maternal B'!E4 -> 11.3 | C4: ='Mini Maternal B'!I4 -> 25-50 | H4: Peso (kg) | I4: ='Mini Maternal B'!E9 -> 14.8 | J4: ='Mini Maternal B'!I9 -> 85-95
A5: Estatura (m) | B5: ='Mini Maternal B'!F4 -> 0.85 | C5: ='Mini Maternal B'!J4 -> 25-50 | H5: Estatura (m) | I5: ='Mini Maternal B'!F9 -> 0.94 | J5: ='Mini Maternal B'!J9 -> 75-85
A6: IMC (kg/m²) | B6: ='Mini Maternal B'!G4 -> 15.640138 | C6: ='Mini Maternal B'!H4 -> 25-50 | H6: IMC (kg/m²) | I6: ='Mini Maternal B'!G9 -> 16.74966 | J6: ='Mini Maternal B'!H9 -> 75-85
A7: Diagnóstico nutricional | B7: ='Mini Maternal B'!K4 -> ADEQUADO | H7: Diagnóstico nutricional | I7: ='Mini Maternal B'!K9 -> ADEQUADO
A9: Nome | B9: ='Mini Maternal B'!A5 -> Giovanna Gianini Freitas | E9: DN | F9: ='Mini Maternal B'!B5 -> 44758 | H9: Nome | I9: ='Mini Maternal B'!A10 -> Malu Costa M. Pereira | L9: DN | M9: ='Mini Maternal B'!B10 -> 44843
A10: Nutricionista: Carina C. R. Xavier - CRN-3: 20.044 | H10: Nutricionista: Carina C. R. Xavier - CRN-3: 20.044
A11: Data | B11: ='Mini Maternal B'!C5 -> 45729 | C11: Percentil | D11: Idade (anos) | F11: ='Mini Maternal B'!D5 -> 2a 7m | H11: Data | I11: ='Mini Maternal B'!C10 -> 45729 | J11: Percentil | K11: Idade (anos) | M11: ='Mini Maternal B'!D10 -> 2a 5m
A12: Peso (kg) | B12: ='Mini Maternal B'!E5 -> 14 | C12: ='Mini Maternal B'!I5 -> 50-75 | H12: Peso (kg) | I12: ='Mini Maternal B'!E10 -> 11.6 | J12: ='Mini Maternal B'!I10 -> 25-50
A13: Estatura (m) | B13: ='Mini Maternal B'!F5 -> 0.94 | C13: ='Mini Maternal B'!J5 -> 75-85 | H13: Estatura (m) | I13: ='Mini Maternal B'!F10 -> 0.87 | J13: ='Mini Maternal B'!J10 -> 15-25
A14: IMC (kg/m²) | B14: ='Mini Maternal B'!G5 -> 15.844273 | C14: ='Mini Maternal B'!H5 -> 50-75 | H14: IMC (kg/m²) | I14: ='Mini Maternal B'!G10 -> 15.32567 | J14: ='Mini Maternal B'!H10 -> 25-50
A15: Diagnóstico nutricional | B15: ='Mini Maternal B'!K5 -> ADEQUADO | H15: Diagnóstico nutricional | I15: ='Mini Maternal B'!K10 -> ADEQUADO
A17: Nome | B17: ='Mini Maternal B'!A6 -> Heitor F. S. Lourenço | E17: DN | F17: ='Mini Maternal B'!B6 -> 44845 | H17: Nome | I17: ='Mini Maternal B'!A11 -> Noah Lacativa Penna | L17: DN | M17: ='Mini Maternal B'!B11 -> 44700
A18: Nutricionista: Carina C. R. Xavier - CRN-3: 20.044 | H18: Nutricionista: Carina C. R. Xavier - CRN-3: 20.044
A19: Data | B19: ='Mini Maternal B'!C6 -> 0 | C19: Percentil | D19: Idade (anos) | F19: ='Mini Maternal B'!D6 -> 0 | H19: Data | I19: ='Mini Maternal B'!C11 -> 45729 | J19: Percentil | K19: Idade (anos) | M19: ='Mini Maternal B'!D11 -> 2a 9m
A20: Peso (kg) | B20: ='Mini Maternal B'!E6 -> 0 | C20: ='Mini Maternal B'!I6 -> 0 | H20: Peso (kg) | I20: ='Mini Maternal B'!E11 -> 15.1 | J20: ='Mini Maternal B'!I11 -> 75-85
A21: Estatura (m) | B21: ='Mini Maternal B'!F6 -> 0 | C21: ='Mini Maternal B'!J6 -> 0 | H21: Estatura (m) | I21: ='Mini Maternal B'!F11 -> 0.97 | J21: ='Mini Maternal B'!J11 -> 75-85
A22: IMC (kg/m²) | B22: ='Mini Maternal B'!G6 -> #DIV/0! | C22: ='Mini Maternal B'!H6 -> 0 | H22: IMC (kg/m²) | I22: ='Mini Maternal B'!G11 -> 16.048464 | J22: ='Mini Maternal B'!H11 -> 50-75
A23: Diagnóstico nutricional | B23: ='Mini Maternal B'!K6 -> 0 | H23: Diagnóstico nutricional | I23: ='Mini Maternal B'!K11 -> ADEQUADO
A25: Nome | B25: ='Mini Maternal B'!A7 -> Henrique M. Gonçalves | E25: DN | F25: ='Mini Maternal B'!B7 -> 44668 | H25: Nome | I25: ='Mini Maternal B'!A12 -> Pedro M.Augusto de Souza | L25: DN | M25: ='Mini Maternal B'!B12 -> 44718
A26: Nutricionista: Carina C. R. Xavier - CRN-3: 20.044 | H26: Nutricionista: Carina C. R. Xavier - CRN-3: 20.044
A27: Data | B27: ='Mini Maternal B'!C7 -> 45729 | C27: Percentil | D27: Idade (anos) | F27: ='Mini Maternal B'!D7 -> 2a 10m | H27: Data | I27: ='Mini Maternal B'!C12 -> 45729 | J27: Percentil | K27: Idade (anos) | M27: ='Mini Maternal B'!D12 -> 2a 9m
A28: Peso (kg) | B28: ='Mini Maternal B'!E7 -> 14.4 | C28: ='Mini Maternal B'!I21 -> 0 | H28: Peso (kg) | I28: ='Mini Maternal B'!E12 -> 15.3 | J28: ='Mini Maternal B'!I12 -> 75-85
A29: Estatura (m) | B29: ='Mini Maternal B'!F7 -> 1 | C29: ='Mini Maternal B'!J21 -> 0 | H29: Estatura (m) | I29: ='Mini Maternal B'!F12 -> 0.98 | J29: ='Mini Maternal B'!J12 -> 85-95
A30: IMC (kg/m²) | B30: ='Mini Maternal B'!G7 -> 14.4 | C30: ='Mini Maternal B'!H21 -> 0 | H30: IMC (kg/m²) | I30: ='Mini Maternal B'!G12 -> 15.930862 | J30: ='Mini Maternal B'!H12 -> 50-75
A31: Diagnóstico nutricional | B31: ='Mini Maternal B'!K7 -> ADEQUADO | H31: Diagnóstico nutricional | I31: ='Mini Maternal B'!K12 -> ADEQUADO
A33: Nome | B33: ='Mini Maternal B'!A8 -> Jorge Cavalheiro Mauá Diba | E33: DN | F33: ='Mini Maternal B'!B8 -> 44743 | H33: Nome | I33: ='Mini Maternal B'!A13 -> Rafaela Saori Teruya Lima | L33: DN | M33: ='Mini Maternal B'!B13 -> 44994
A34: Nutricionista: Carina C. R. Xavier - CRN-3: 20.044 | H34: Nutricionista: Carina C. R. Xavier - CRN-3: 20.044
A35: Data | B35: ='Mini Maternal B'!C8 -> 45729 | C35: Percentil | D35: Idade (anos) | F35: ='Mini Maternal B'!D8 -> 2a 8m | H35: Data | I35: ='Mini Maternal B'!C13 -> 0 | J35: Percentil | K35: Idade (anos) | M35: ='Mini Maternal B'!D13 -> 0
A36: Peso (kg) | B36: ='Mini Maternal B'!E8 -> 16 | C36: ='Mini Maternal B'!I29 -> 0 | H36: Peso (kg) | I36: ='Mini Maternal B'!E13 -> 0 | J36: ='Mini Maternal B'!I13 -> 0
A37: Estatura (m) | B37: ='Mini Maternal B'!F8 -> 0.95 | C37: ='Mini Maternal B'!J29 -> 0 | H37: Estatura (m) | I37: ='Mini Maternal B'!F13 -> 0 | J37: ='Mini Maternal B'!J13 -> 0
A38: IMC (kg/m²) | B38: ='Mini Maternal B'!G8 -> 17.728532 | C38: ='Mini Maternal B'!H29 -> 0 | H38: IMC (kg/m²) | I38: ='Mini Maternal B'!G13 -> #DIV/0! | J38: ='Mini Maternal B'!H13 -> 0
A39: Diagnóstico nutricional | B39: ='Mini Maternal B'!K8 -> SOBREPESO | H39: Diagnóstico nutricional | I39: ='Mini Maternal B'!K13 -> 0
H41: Nome | I41: ='Mini Maternal B'!A14 -> Valentina Travagini Garcia | L41: DN | M41: ='Mini Maternal B'!B14 -> 44813
H42: Nutricionista: Carina C. R. Xavier - CRN-3: 20.044
H43: Data | I43: ='Mini Maternal B'!C14 -> 45729 | J43: Percentil | K43: Idade (anos) | M43: ='Mini Maternal B'!D14 -> 2a 6m
H44: Peso (kg) | I44: ='Mini Maternal B'!E14 -> 12.6 | J44: ='Mini Maternal B'!I14 -> 25-50
H45: Estatura (m) | I45: ='Mini Maternal B'!F14 -> 0.89 | J45: ='Mini Maternal B'!J14 -> 25-50
...

Sheet Maternal A 
A1: Avaliação Nutricional 2025/1 - Maternal A
B3: Data de Nasc. | C3: Data pesagem | D3: Idade | E3: Peso (kg) | F3: Estatura (m) | G3: IMC (kg/m²) | H3: IMC/I | I3: P/I | J3: E/I | K3: DIAGNÓSTICO NUTRICIONAL | N3: Menina | O3: Menino
A4: Beatriz Tanahashi Pereira | B4: 44489 | C4: 45729 | D4: 3a 4m | E4: 15 | F4: 0.96 | G4: =E4/(F4*F4) -> 16.276042 | H4: 75 | I4: 50-75 | J4: 25-50 | K4: ADEQUADO | M4: Baixo peso
A5: Bernardo Rolão M. de Lima | B5: 44418 | C5: 45729 | D5: 3a 7m | E5: 18.1 | F5: 1.03 | G5: =E5/(F5*F5) -> 17.060986 | H5: 85-95 | I5: 85-95 | J5: 50-75 | K5: SOBREPESO | M5: Adequado | N5: 1 | O5: 2
A6: Catarina Saquete Rodrigues | B6: 44649 | G6: =E6/(F6*F6) -> #DIV/0! | M6: Sobrepeso | O6: 2
A7: Gabriel P. Cappi Ferreira | B7: 44504 | G7: =E7/(F7*F7) -> #DIV/0! | M7: Obesidade
A8: Gabriela Vello de Moraes | B8: 44455 | G8: =E8/(F8*F8) -> #DIV/0! | M8: Total / gênero | N8: =SUM(N5:N7) -> 1 | O8: =SUM(O5:O7) -> 4
A9: João Hideki Aoyama Ota | B9: 44596 | G9: =E9/(F9*F9) -> #DIV/0! | M9: Total | O9: =SUM(N8:O8) -> 5
A10: João Pedro de M. Torres | B10: 44495 | C10: 45729 | D10: 3a 4m | E10: 15.4 | F10: 0.98 | G10: =E10/(F10*F10) -> 16.034985 | H10: 50-75 | I10: 50-75 | J10: 25-50 | K10: ADEQUADO
A11: Leonardo Mônaco André | B11: 44377 | G11: =E11/(F11*F11) -> #DIV/0!
A12: Luca Torres Borini | B12: 44398 | C12: 45729 | D12: 3a 7m | E12: 17.9 | F12: 1 | G12: =E12/(F12*F12) -> 17.9 | H12: 95-97 | I12: 85-95 | J12: 25-50 | K12: SOBREPESO
A13: Theo Kenji Kuba Imamura | B13: 44605 | C13: 45729 | D13: 3a 1m | E13: 12.6 | F13: 0.92 | G13: =E13/(F13*F13) -> 14.886578 | H13: 25-50 | I13: 5-15. | J13: 5-15. | K13: ADEQUADO

Sheet Av. Individual Maternal A
A1: Nome | B1: ='Maternal A '!A4 -> Beatriz Tanahashi Pereira | E1: DN | F1: ='Maternal A '!B4 -> 44489 | H1: Nome | I1: ='Maternal A '!A9 -> João Hideki Aoyama Ota | L1: DN | M1: ='Maternal A '!B9 -> 44596
A2: Nutricionista: Carina C. R. Xavier - CRN-3: 20.044 | H2: Nutricionista: Carina C. R. Xavier - CRN-3: 20.044
A3: Data | B3: ='Maternal A '!C4 -> 45729 | C3: Percentil | D3: Idade (anos) | F3: ='Maternal A '!D4 -> 3a 4m | H3: Data | I3: ='Maternal A '!C9 -> 0 | J3: Percentil | K3: Idade (anos) | M3: ='Maternal A '!D9 -> 0
A4: Peso (kg) | B4: ='Maternal A '!E4 -> 15 | C4: ='Maternal A '!I4 -> 50-75 | H4: Peso (kg) | I4: ='Maternal A '!E9 -> 0 | J4: ='Maternal A '!I9 -> 0
A5: Estatura (m) | B5: ='Maternal A '!F4 -> 0.96 | C5: ='Maternal A '!J4 -> 25-50 | H5: Estatura (m) | I5: ='Maternal A '!F9 -> 0 | J5: ='Maternal A '!J9 -> 0
A6: IMC (kg/m²) | B6: ='Maternal A '!G4 -> 16.276042 | C6: ='Maternal A '!H4 -> 75 | H6: IMC (kg/m²) | I6: ='Maternal A '!G9 -> #DIV/0! | J6: ='Maternal A '!H9 -> 0
A7: Diagnóstico nutricional | B7: ='Maternal A '!K4 -> ADEQUADO | H7: Diagnóstico nutricional | I7: ='Maternal A '!K9 -> 0
A9: Nome | B9: ='Maternal A '!A5 -> Bernardo Rolão M. de Lima | E9: DN | F9: ='Maternal A '!B5 -> 44418 | H9: Nome | I9: ='Maternal A '!A10 -> João Pedro de M. Torres | L9: DN | M9: ='Maternal A '!B10 -> 44495
A10: Nutricionista: Carina C. R. Xavier - CRN-3: 20.044 | H10: Nutricionista: Carina C. R. Xavier - CRN-3: 20.044
A11: Data | B11: ='Maternal A '!C5 -> 45729 | C11: Percentil | D11: Idade (anos) | F11: ='Maternal A '!D5 -> 3a 7m | H11: Data | I11: ='Maternal A '!C10 -> 45729 | J11: Percentil | K11: Idade (anos) | M11: ='Maternal A '!D10 -> 3a 4m
A12: Peso (kg) | B12: ='Maternal A '!E5 -> 18.1 | C12: ='Maternal A '!I5 -> 85-95 | H12: Peso (kg) | I12: ='Maternal A '!E10 -> 15.4 | J12: ='Maternal A '!I10 -> 50-75
A13: Estatura (m) | B13: ='Maternal A '!F5 -> 1.03 | C13: ='Maternal A '!J5 -> 50-75 | H13: Estatura (m) | I13: ='Maternal A '!F10 -> 0.98 | J13: ='Maternal A '!J10 -> 25-50
A14: IMC (kg/m²) | B14: ='Maternal A '!G5 -> 17.060986 | C14: ='Maternal A '!H5 -> 85-95 | H14: IMC (kg/m²) | I14: ='Maternal A '!G10 -> 16.034985 | J14: ='Maternal A '!H10 -> 50-75
A15: Diagnóstico nutricional | B15: ='Maternal A '!K5 -> SOBREPESO | H15: Diagnóstico nutricional | I15: ='Maternal A '!K10 -> ADEQUADO
A17: Nome | B17: ='Maternal A '!A6 -> Catarina Saquete Rodrigues | E17: DN | F17: ='Maternal A '!B6 -> 44649 | H17: Nome | I17: ='Maternal A '!A11 -> Leonardo Mônaco André | L17: DN | M17: ='Maternal A '!B11 -> 44377
A18: Nutricionista: Carina C. R. Xavier - CRN-3: 20.044 | H18: Nutricionista: Carina C. R. Xavier - CRN-3: 20.044
A19: Data | B19: ='Maternal A '!C6 -> 0 | C19: Percentil | D19: Idade (anos) | F19: ='Maternal A '!D6 -> 0 | H19: Data | I19: ='Maternal A '!C11 -> 0 | J19: Percentil | K19: Idade (anos) | M19: ='Maternal A '!D11 -> 0
A20: Peso (kg) | B20: ='Maternal A '!E6 -> 0 | C20: ='Maternal A '!I6 -> 0 | H20: Peso (kg) | I20: ='Maternal A '!E11 -> 0 | J20: ='Maternal A '!I11 -> 0
A21: Estatura (m) | B21: ='Maternal A '!F6 -> 0 | C21: ='Maternal A '!J6 -> 0 | H21: Estatura (m) | I21: ='Maternal A '!F11 -> 0 | J21: ='Maternal A '!J11 -> 0
A22: IMC (kg/m²) | B22: ='Maternal A '!G6 -> #DIV/0! | C22: ='Maternal A '!H6 -> 0 | H22: IMC (kg/m²) | I22: ='Maternal A '!G11 -> #DIV/0! | J22: ='Maternal A '!H11 -> 0
A23: Diagnóstico nutricional | B23: ='Maternal A '!K6 -> 0 | H23: Diagnóstico nutricional | I23: ='Maternal A '!K11 -> 0
A25: Nome | B25: ='Maternal A '!A7 -> Gabriel P. Cappi Ferreira | E25: DN | F25: ='Maternal A '!B7 -> 44504 | H25: Nome | I25: ='Maternal A '!A12 -> Luca Torres Borini | L25: DN | M25: ='Maternal A '!B12 -> 44398
A26: Nutricionista: Carina C. R. Xavier - CRN-3: 20.044 | H26: Nutricionista: Carina C. R. Xavier - CRN-3: 20.044
A27: Data | B27: ='Maternal A '!C7 -> 0 | C27: Percentil | D27: Idade (anos) | F27: ='Maternal A '!D7 -> 0 | H27: Data | I27: ='Maternal A '!C12 -> 45729 | J27: Percentil | K27: Idade (anos) | M27: ='Maternal A '!D12 -> 3a 7m
A28: Peso (kg) | B28: ='Maternal A '!E7 -> 0 | C28: ='Maternal A '!I7 -> 0 | H28: Peso (kg) | I28: ='Maternal A '!E12 -> 17.9 | J28: ='Maternal A '!I12 -> 85-95
A29: Estatura (m) | B29: ='Maternal A '!F7 -> 0 | C29: ='Maternal A '!J7 -> 0 | H29: Estatura (m) | I29: ='Maternal A '!F12 -> 1 | J29: ='Maternal A '!J12 -> 25-50
A30: IMC (kg/m²) | B30: ='Maternal A '!G7 -> #DIV/0! | C30: ='Maternal A '!H7 -> 0 | H30: IMC (kg/m²) | I30: ='Maternal A '!G12 -> 17.9 | J30: ='Maternal A '!H12 -> 95-97
A31: Diagnóstico nutricional | B31: ='Maternal A '!K7 -> 0 | H31: Diagnóstico nutricional | I31: ='Maternal A '!K12 -> SOBREPESO
A33: Nome | B33: ='Maternal A '!A8 -> Gabriela Vello de Moraes | E33: DN | F33: ='Maternal A '!B8 -> 44455 | H33: Nome | I33: ='Maternal A '!A13 -> Theo Kenji Kuba Imamura | L33: DN | M33: ='Maternal A '!B13 -> 44605
A34: Nutricionista: Carina C. R. Xavier - CRN-3: 20.044 | H34: Nutricionista: Carina C. R. Xavier - CRN-3: 20.044
A35: Data | B35: ='Maternal A '!C8 -> 0 | C35: Percentil | D35: Idade (anos) | F35: ='Maternal A '!D8 -> 0 | H35: Data | I35: ='Maternal A '!C13 -> 45729 | J35: Percentil | K35: Idade (anos) | M35: ='Maternal A '!D13 -> 3a 1m
A36: Peso (kg) | B36: ='Maternal A '!E8 -> 0 | C36: ='Maternal A '!I8 -> 0 | H36: Peso (kg) | I36: ='Maternal A '!E13 -> 12.6 | J36: ='Maternal A '!I13 -> 5-15.
A37: Estatura (m) | B37: ='Maternal A '!F8 -> 0 | C37: ='Maternal A '!J8 -> 0 | H37: Estatura (m) | I37: ='Maternal A '!F13 -> 0.92 | J37: ='Maternal A '!J13 -> 5-15.
A38: IMC (kg/m²) | B38: ='Maternal A '!G8 -> #DIV/0! | C38: ='Maternal A '!H8 -> 0 | H38: IMC (kg/m²) | I38: ='Maternal A '!G13 -> 14.886578 | J38: ='Maternal A '!H13 -> 25-50
A39: Diagnóstico nutricional | B39: ='Maternal A '!K8 -> 0 | H39: Diagnóstico nutricional | I39: ='Maternal A '!K13 -> ADEQUADO
H41: Nome | I41: ='Maternal A '!A14 -> 0 | L41: DN | M41: ='Maternal A '!B14 -> 0
H42: Nutricionista: Carina C. R. Xavier - CRN-3: 20.044
H43: Data | I43: ='Maternal A '!C14 -> 0 | J43: Percentil | K43: Idade (anos) | M43: ='Maternal A '!D14 -> 0
H44: Peso (kg) | I44: ='Maternal A '!E14 -> 0 | J44: ='Maternal A '!I14 -> 0
H45: Estatura (m) | I45: ='Maternal A '!F14 -> 0 | J45: ='Maternal A '!J14 -> 0
...

Sheet Maternal B
A1: Avaliação Nutricional 2025/1 - Maternal B
B3: Data de Nasc. | C3: Data pesagem | D3: Idade | E3: Peso (kg) | F3: Estatura (m) | G3: IMC (kg/m²) | H3: IMC/I | I3: P/I | J3: E/I | K3: DIAGNÓSTICO NUTRICIONAL | N3: Menina | O3: Menino
A4: Alice Aguiar Rodrigues | B4: 44538 | C4: 45729 | D4: 3a 3m | E4: 17 | F4: 1.03 | G4: =E4/(F4*F4) -> 16.02413 | H4: 50-75 | I4: 85-95 | J4: 85-95 | K4: ADEQUADO | M4: Baixo peso
A5: Alice Cardoso Montenegro | B5: 44529 | C5: 45729 | D5: 3a 3m | E5: 11.8 | F5: 0.9 | G5: =E5/(F5*F5) -> 14.567901 | H5: 25-50 | I5: 5-15. | J5: 3-5. | K5: ADEQUADO | M5: Adequado | N5: 5 | O5: 1
A6: Beatriz Cury Aquino | B6: 44346 | C6: 45729 | D6: 3a 9m | E6: 14 | F6: 0.97 | G6: =E6/(F6*F6) -> 14.879371 | H6: 25-50 | I6: 15-25 | J6: 15-25 | K6: ADEQUADO | M6: Sobrepeso | N6: 1 | O6: 2
A7: Laura Lentini Fernandes | B7: 44613 | C7: 45729 | D7: 3a | E7: 13 | F7: 0.92 | G7: =E7/(F7*F7) -> 15.359168 | H7: 50 | I7: 25-50 | J7: 15-25 | K7: ADEQUADO | M7: Obesidade
A8: Manuella Boffi O. da Cruz | B8: 44388 | C8: 45729 | D8: 3a 8m | E8: 19.2 | F8: 1.04 | G8: =E8/(F8*F8) -> 17.751479 | H8: 95 | I8: 85-95 | J8: 75-85 | K8: SOBREPESO | M8: Total / gênero | N8: =SUM(N5:N7) -> 6 | O8: =SUM(O5:O7) -> 3
A9: Maria Eduarda M. Bordinhon | B9: 44601 | C9: 45729 | D9: 3a 1m | E9: 14.9 | F9: 0.98 | G9: =E9/(F9*F9) -> 15.514369 | H9: 50-75 | I9: 50-75 | J9: 50-75 | K9: ADEQUADO | M9: Total | O9: =SUM(N8:O8) -> 9
A10: Matheus G.A. Pereira | B10: 44287 | C10: 45729 | D10: 3a 11m | E10: 18.1 | F10: 1.1 | G10: =E10/(F10*F10) -> 14.958678 | H10: 25-50 | I10: 75-85 | J10: 95-97 | K10: ADEQUADO
A11: Otavio F. Takenaka | B11: 44328 | C11: 45729 | D11: 3a 10m | E11: 17.1 | F11: 1 | G11: =E11/(F11*F11) -> 17.1 | H11: 85-95 | I11: 50-75 | J11: 25-50 | K11: SOBREPESO
A12: Theo Batista Lucena | B12: 44317 | C12: 45729 | D12: 3a 10m | E12: 18.9 | F12: 1.06 | G12: =E12/(F12*F12) -> 16.820933 | H12: 85-95 | I12: 85-95 | J12: 75-85 | K12: SOBREPESO

Sheet Av. Individual Maternal B
A1: Nome | B1: ='Maternal B'!A4 -> Alice Aguiar Rodrigues | E1: DN | F1: ='Maternal B'!B4 -> 44538 | H1: Nome | I1: ='Maternal B'!A9 -> Maria Eduarda M. Bordinhon | L1: DN | M1: ='Maternal B'!B9 -> 44601
A2: Nutricionista: Carina C. R. Xavier - CRN-3: 20.044 | H2: Nutricionista: Carina C. R. Xavier - CRN-3: 20.044
A3: Data | B3: ='Maternal B'!C4 -> 45729 | C3: Percentil | D3: Idade (anos) | F3: ='Maternal B'!D4 -> 3a 3m | H3: Data | I3: ='Maternal B'!C9 -> 45729 | J3: Percentil | K3: Idade (anos) | M3: ='Maternal B'!D9 -> 3a 1m
A4: Peso (kg) | B4: ='Maternal B'!E4 -> 17 | C4: ='Maternal B'!I4 -> 85-95 | H4: Peso (kg) | I4: ='Maternal B'!E9 -> 14.9 | J4: ='Maternal B'!I9 -> 50-75
A5: Estatura (m) | B5: ='Maternal B'!F4 -> 1.03 | C5: ='Maternal B'!J4 -> 85-95 | H5: Estatura (m) | I5: ='Maternal B'!F9 -> 0.98 | J5: ='Maternal B'!J9 -> 50-75
A6: IMC (kg/m²) | B6: ='Maternal B'!G4 -> 16.02413 | C6: ='Maternal B'!H4 -> 50-75 | H6: IMC (kg/m²) | I6: ='Maternal B'!G9 -> 15.514369 | J6: ='Maternal B'!H9 -> 50-75
A7: Diagnóstico nutricional | B7: ='Maternal B'!K4 -> ADEQUADO | H7: Diagnóstico nutricional | I7: ='Maternal B'!K9 -> ADEQUADO
A9: Nome | B9: ='Maternal B'!A5 -> Alice Cardoso Montenegro | E9: DN | F9: ='Maternal B'!B5 -> 44529 | H9: Nome | I9: ='Maternal B'!A10 -> Matheus G.A. Pereira | L9: DN | M9: ='Maternal B'!B10 -> 44287
A10: Nutricionista: Carina C. R. Xavier - CRN-3: 20.044 | H10: Nutricionista: Carina C. R. Xavier - CRN-3: 20.044
A11: Data | B11: ='Maternal B'!C5 -> 45729 | C11: Percentil | D11: Idade (anos) | F11: ='Maternal B'!D5 -> 3a 3m | H11: Data | I11: ='Maternal B'!C10 -> 45729 | J11: Percentil | K11: Idade (anos) | M11: ='Maternal B'!D10 -> 3a 11m
A12: Peso (kg) | B12: ='Maternal B'!E5 -> 11.8 | C12: ='Maternal B'!I5 -> 5-15. | H12: Peso (kg) | I12: ='Maternal B'!E10 -> 18.1 | J12: ='Maternal B'!I10 -> 75-85
A13: Estatura (m) | B13: ='Maternal B'!F5 -> 0.9 | C13: ='Maternal B'!J5 -> 3-5. | H13: Estatura (m) | I13: ='Maternal B'!F10 -> 1.1 | J13: ='Maternal B'!J10 -> 95-97
A14: IMC (kg/m²) | B14: ='Maternal B'!G5 -> 14.567901 | C14: ='Maternal B'!H5 -> 25-50 | H14: IMC (kg/m²) | I14: ='Maternal B'!G10 -> 14.958678 | J14: ='Maternal B'!H10 -> 25-50
A15: Diagnóstico nutricional | B15: ='Maternal B'!K5 -> ADEQUADO | H15: Diagnóstico nutricional | I15: ='Maternal B'!K10 -> ADEQUADO
A17: Nome | B17: ='Maternal B'!A6 -> Beatriz Cury Aquino | E17: DN | F17: ='Maternal B'!B6 -> 44346 | H17: Nome | I17: =#REF! -> #REF! | L17: DN | M17: =#REF! -> #REF!
A18: Nutricionista: Carina C. R. Xavier - CRN-3: 20.044 | H18: Nutricionista: Carina C. R. Xavier - CRN-3: 20.044
A19: Data | B19: ='Maternal B'!C6 -> 45729 | C19: Percentil | D19: Idade (anos) | F19: ='Maternal B'!D6 -> 3a 9m | H19: Data | I19: =#REF! -> #REF! | J19: Percentil | K19: Idade (anos) | M19: =#REF! -> #REF!
A20: Peso (kg) | B20: ='Maternal B'!E6 -> 14 | C20: ='Maternal B'!I6 -> 15-25 | H20: Peso (kg) | I20: =#REF! -> #REF! | J20: =#REF! -> #REF!
A21: Estatura (m) | B21: ='Maternal B'!F6 -> 0.97 | C21: ='Maternal B'!J6 -> 15-25 | H21: Estatura (m) | I21: =#REF! -> #REF! | J21: =#REF! -> #REF!
A22: IMC (kg/m²) | B22: ='Maternal B'!G6 -> 14.879371 | C22: ='Maternal B'!H6 -> 25-50 | H22: IMC (kg/m²) | I22: =#REF! -> #REF! | J22: =#REF! -> #REF!
A23: Diagnóstico nutricional | B23: ='Maternal B'!K20 -> 0 | H23: Diagnóstico nutricional | I23: =#REF! -> #REF!
A25: Nome | B25: ='Maternal B'!A7 -> Laura Lentini Fernandes | E25: DN | F25: ='Maternal B'!B7 -> 44613 | H25: Nome | I25: =#REF! -> #REF! | L25: DN | M25: =#REF! -> #REF!
A26: Nutricionista: Carina C. R. Xavier - CRN-3: 20.044 | H26: Nutricionista: Carina C. R. Xavier - CRN-3: 20.044
A27: Data | B27: ='Maternal B'!C7 -> 45729 | C27: Percentil | D27: Idade (anos) | F27: ='Maternal B'!D7 -> 3a | H27: Data | I27: =#REF! -> #REF! | J27: Percentil | K27: Idade (anos) | M27: =#REF! -> #REF!
A28: Peso (kg) | B28: ='Maternal B'!E7 -> 13 | C28: ='Maternal B'!I7 -> 25-50 | H28: Peso (kg) | I28: =#REF! -> #REF! | J28: =#REF! -> #REF!
A29: Estatura (m) | B29: ='Maternal B'!F7 -> 0.92 | C29: ='Maternal B'!J7 -> 15-25 | H29: Estatura (m) | I29: =#REF! -> #REF! | J29: =#REF! -> #REF!
A30: IMC (kg/m²) | B30: ='Maternal B'!G7 -> 15.359168 | C30: ='Maternal B'!H7 -> 50 | H30: IMC (kg/m²) | I30: =#REF! -> #REF! | J30: =#REF! -> #REF!
A31: Diagnóstico nutricional | B31: ='Maternal B'!K7 -> ADEQUADO | H31: Diagnóstico nutricional | I31: =#REF! -> #REF!
A33: Nome | B33: ='Maternal B'!A8 -> Manuella Boffi O. da Cruz | E33: DN | F33: ='Maternal B'!B8 -> 44388 | H33: Nome | I33: ='Maternal B'!#REF! -> #REF! | L33: DN | M33: ='Maternal B'!#REF! -> #REF!
A34: Nutricionista: Carina C. R. Xavier - CRN-3: 20.044 | H34: Nutricionista: Carina C. R. Xavier - CRN-3: 13.044
A35: Data | B35: ='Maternal B'!C8 -> 45729 | C35: Percentil | D35: Idade (anos) | F35: ='Maternal B'!D8 -> 3a 8m | H35: Data | I35: ='Maternal B'!#REF! -> #REF! | J35: Percentil | K35: Idade (anos) | M35: ='Maternal B'!#REF! -> #REF!
A36: Peso (kg) | B36: ='Maternal B'!E8 -> 19.2 | C36: ='Maternal B'!I8 -> 85-95 | H36: Peso (kg) | I36: ='Maternal B'!#REF! -> #REF! | J36: ='Maternal B'!#REF! -> #REF!
A37: Estatura (m) | B37: ='Maternal B'!F8 -> 1.04 | C37: ='Maternal B'!J8 -> 75-85 | H37: Estatura (m) | I37: ='Maternal B'!#REF! -> #REF! | J37: ='Maternal B'!#REF! -> #REF!
A38: IMC (kg/m²) | B38: ='Maternal B'!G8 -> 17.751479 | C38: ='Maternal B'!H8 -> 95 | H38: IMC (kg/m²) | I38: ='Maternal B'!#REF! -> #REF! | J38: ='Maternal B'!#REF! -> #REF!
A39: Diagnóstico nutricional | B39: ='Maternal B'!K8 -> SOBREPESO | H39: Diagnóstico nutricional | I39: ='Maternal B'!#REF! -> #REF!

Sheet Maternal C
A1: Avaliação Nutricional 2025/1 - Maternal C
B3: Data de Nasc. | C3: Data pesagem | D3: Idade | E3: Peso (kg) | F3: Estatura (m) | G3: IMC (kg/m²) | H3: IMC/I | I3: P/I | J3: E/I | K3: DIAGNÓSTICO NUTRICIONAL | N3: Menina | O3: Menino
A4: Beatriz Antonella F. Real | B4: 44505 | C4: 45729 | D4: 3a 4m | E4: 16.6 | F4: 0.98 | G4: =E4/(F4*F4) -> 17.284465 | H4: 85-95 | I4: 75-85 | J4: 50-75 | K4: SOBREPESO | M4: Baixo peso
A5: Estela Manchini Tateo | B5: 44540 | C5: 45729 | D5: 3a 3m | E5: 14.1 | F5: 0.92 | G5: =E5/(F5*F5) -> 16.65879 | H5: 75-85 | I5: 25-50 | J5: 5-15. | K5: ADEQUADO | M5: Adequado | N5: 4 | O5: 2
A6: Gael Pasqualin Modesto | B6: 44471 | C6: 45729 | D6: 3a 5m | E6: 13 | F6: 0.93 | G6: =E6/(F6*F6) -> 15.030639 | H6: 25-50 | I6: 5-15. | J6: 5-15. | K6: ADEQUADO | M6: Sobrepeso | N6: 1 | O6: 1
A7: João Victor C. de Morais | B7: 44413 | C7: 45729 | D7: 3a 7m | E7: 16.7 | F7: 0.99 | G7: =E7/(F7*F7) -> 17.039078 | H7: 85-95 | I7: 50-75 | J7: 25-50 | K7: SOBREPESO | M7: Obesidade | O7: 2
A8: Kael H. de P.Watanabe | B8: 44418 | C8: 45729 | D8: 3a 7m | E8: 17.7 | F8: 0.97 | G8: =E8/(F8*F8) -> 18.811776 | H8: > 99 | I8: 85 | J8: 15-25 | K8: OBESIDADE | M8: Total / gênero | N8: =SUM(N5:N7) -> 5 | O8: =SUM(O5:O7) -> 5
A9: Lucas Silvestre Moita | B9: 44622 | C9: 45729 | D9: 3a | E9: 17.3 | F9: 0.95 | G9: =E9/(F9*F9) -> 19.168975 | H9: > 99 | I9: 85-95 | J9: 25-50 | K9: OBESIDADE | M9: Total | O9: =SUM(N8:O8) -> 10
A10: Luísa Miotto Sant'Anna | B10: 44437 | C10: 45729 | D10: 3a 6m | E10: 14.8 | F10: 0.99 | G10: =E10/(F10*F10) -> 15.1005 | H10: 25-50 | I10: 25-50 | J10: 50 | K10: ADEQUADO
A11: Maria Luiza Hobl Genaro | B11: 44332 | C11: 45729 | D11: 3a 9m | E11: 15.2 | F11: 1.02 | G11: =E11/(F11*F11) -> 14.609765 | H11: 25-50 | I11: 25-50 | J11: 50-75 | K11: ADEQUADO
A12: Pedro Teixeira Martins | B12: 44621 | C12: 45729 | D12: 3a | E12: 16.3 | F12: 0.99 | G12: =E12/(F12*F12) -> 16.630956 | H12: 75-85 | I12: 85 | J12: 75-85 | K12: ADEQUADO
A13: Rafaela Codatto Oliani | B13: 44400 | C13: 45729 | D13: 3a 7m | E13: 16.3 | F13: 1.02 | G13: =E13/(F13*F13) -> 15.667051 | H13: 50-75 | I13: 50-75 | J13: 50-75 | K13: ADEQUADO

Sheet Av. Individual Maternal C
A1: Nome | B1: ='Maternal C'!A4 -> Beatriz Antonella F. Real | E1: DN | F1: ='Maternal C'!B4 -> 44505 | H1: Nome | I1: ='Maternal C'!A11 -> Maria Luiza Hobl Genaro | L1: DN | M1: ='Maternal C'!B11 -> 44332
A2: Nutricionista: Carina C. R. Xavier - CRN-3: 20.044 | H2: Nutricionista: Carina C. R. Xavier - CRN-3: 20.044
A3: Data | B3: ='Maternal C'!C4 -> 45729 | C3: Percentil | D3: Idade (anos) | F3: ='Maternal C'!D4 -> 3a 4m | H3: Data | I3: ='Maternal C'!C11 -> 45729 | J3: Percentil | K3: Idade (anos) | M3: ='Maternal C'!D11 -> 3a 9m
A4: Peso (kg) | B4: ='Maternal C'!E4 -> 16.6 | C4: ='Maternal C'!I4 -> 75-85 | H4: Peso (kg) | I4: ='Maternal C'!E11 -> 15.2 | J4: ='Maternal C'!I11 -> 25-50
A5: Estatura (m) | B5: ='Maternal C'!F4 -> 0.98 | C5: ='Maternal C'!J4 -> 50-75 | H5: Estatura (m) | I5: ='Maternal C'!F11 -> 1.02 | J5: ='Maternal C'!J11 -> 50-75
A6: IMC (kg/m²) | B6: ='Maternal C'!G4 -> 17.284465 | C6: ='Maternal C'!H4 -> 85-95 | H6: IMC (kg/m²) | I6: ='Maternal C'!G11 -> 14.609765 | J6: ='Maternal C'!H11 -> 25-50
A7: Diagnóstico nutricional | B7: ='Maternal C'!K4 -> SOBREPESO | H7: Diagnóstico nutricional | I7: ='Maternal C'!K11 -> ADEQUADO
A9: Nome | B9: ='Maternal C'!A5 -> Estela Manchini Tateo | E9: DN | F9: ='Maternal C'!B5 -> 44540 | H9: Nome | I9: ='Maternal C'!A12 -> Pedro Teixeira Martins | L9: DN | M9: ='Maternal C'!B12 -> 44621
A10: Nutricionista: Carina C. R. Xavier - CRN-3: 20.044 | H10: Nutricionista: Carina C. R. Xavier - CRN-3: 20.044
